Workbook

Sheet products
A1: לכלול להצעת המחיר? | B1: ברקוד | C1: תיאור פריט | D1: מחיר מכירה | G1: סהכ משקל | H1: מעמ (0לא,1כן) | I1: ניתן להנחות (0לא,1כן) | J1: מספר קבוצה | K1: שם קבוצה | L1: מספר מחלקה | M1: שם מחלקה | N1: מספר ספק | O1: שם ספק | P1: מחיר לק"ג
B2: 100001158002 | D2: 79 | G2: כשר לפסח לאוכלי קטניות שתפ"ו | H2: 1 | I2: 1 | J2: 3 | K2: פיצוחים לא קלוי | L2: 4 | M2: אגוזים טבעים | N2: 16 | O2: צ'רחי אברהם | P2: =IFERROR(D2/(VALUE(LEFT(TRIM(MID(G2,FIND("תכולה",G2)+6,20)),FIND(" ",TRIM(MID(G2,FIND("תכולה",G2)+6,20))&" ")-1))/1000),"")
B3: 100058239210 | D3: 99 | G3: פרווה | H3: 1 | I3: 1 | J3: 3 | K3: פיצוחים לא קלוי | L3: 4 | M3: אגוזים טבעים | N3: \N | O3: \N | P3: =IFERROR(D3/(VALUE(LEFT(TRIM(MID(G3,FIND("תכולה",G3)+6,20)),FIND(" ",TRIM(MID(G3,FIND("תכולה",G3)+6,20))&" ")-1))/1000),"")
B4: 10013011090S | C4: סויה קריספי | D4: 4.5 | G4: תכולה 100 | H4: 1 | I4: 1 | J4: 1 | K4: שונות | L4: 4 | M4: אגוזים טבעים | N4: \N | O4: \N | P4: =IFERROR(D4/(VALUE(LEFT(TRIM(MID(G4,FIND("תכולה",G4)+6,20)),FIND(" ",TRIM(MID(G4,FIND("תכולה",G4)+6,20))&" ")-1))/1000),"") -> 45
A5: FALSE | B5: 100508469002 | C5: פיסטוק חלבי מקולף | D5: 85 | G5: \N | H5: 1 | I5: 0 | J5: 1 | K5: שונות | L5: 4 | M5: אגוזים טבעים | N5: 2 | O5: יוסף לוי | P5: =IFERROR(D5/(VALUE(LEFT(TRIM(MID(G5,FIND("תכולה",G5)+6,20)),FIND(" ",TRIM(MID(G5,FIND("תכולה",G5)+6,20))&" ")-1))/1000),"")
A6: FALSE | B6: 1011010158238 | C6: חליטת נענע לימון פחית | D6: 110 | G6: \N | H6: 1 | I6: 1 | J6: 1 | K6: שונות | L6: 4 | M6: אגוזים טבעים | N6: \N | O6: \N | P6: =IFERROR(D6/(VALUE(LEFT(TRIM(MID(G6,FIND("תכולה",G6)+6,20)),FIND(" ",TRIM(MID(G6,FIND("תכולה",G6)+6,20))&" ")-1))/1000),"")
A7: FALSE | B7: 15575304553M | C7: שום שחור גבישי במלחייה | D7: 5 | G7: תכולה 400 | H7: 1 | I7: 1 | J7: 1 | K7: שונות | L7: 4 | M7: אגוזים טבעים | N7: \N | O7: \N | P7: =IFERROR(D7/(VALUE(LEFT(TRIM(MID(G7,FIND("תכולה",G7)+6,20)),FIND(" ",TRIM(MID(G7,FIND("תכולה",G7)+6,20))&" ")-1))/1000),"") -> 12.5
B8: 66643868255S | D8: 3.3 | G8: תכולה 250 | H8: 1 | I8: 1 | J8: 1 | K8: שונות | L8: 4 | M8: אגוזים טבעים | N8: \N | O8: \N | P8: =IFERROR(D8/(VALUE(LEFT(TRIM(MID(G8,FIND("תכולה",G8)+6,20)),FIND(" ",TRIM(MID(G8,FIND("תכולה",G8)+6,20))&" ")-1))/1000),"") -> 13.2
B9: 70007580580S | D9: 5 | G9: תכולה 170 | H9: 0 | I9: 1 | J9: 1 | K9: שונות | L9: 4 | M9: אגוזים טבעים | N9: \N | O9: \N | P9: =IFERROR(D9/(VALUE(LEFT(TRIM(MID(G9,FIND("תכולה",G9)+6,20)),FIND(" ",TRIM(MID(G9,FIND("תכולה",G9)+6,20))&" ")-1))/1000),"") -> 29.411765
B10: 71074022001S | D10: 4.4 | G10: תכולה 200 | H10: 1 | I10: 1 | J10: 1 | K10: שונות | L10: 4 | M10: אגוזים טבעים | N10: \N | O10: \N | P10: =IFERROR(D10/(VALUE(LEFT(TRIM(MID(G10,FIND("תכולה",G10)+6,20)),FIND(" ",TRIM(MID(G10,FIND("תכולה",G10)+6,20))&" ")-1))/1000),"") -> 22
B11: 76037024583L | D11: 9.8 | G11: תכולה 750 | H11: 1 | I11: 1 | J11: 1 | K11: שונות | L11: 4 | M11: אגוזים טבעים | N11: \N | O11: \N | P11: =IFERROR(D11/(VALUE(LEFT(TRIM(MID(G11,FIND("תכולה",G11)+6,20)),FIND(" ",TRIM(MID(G11,FIND("תכולה",G11)+6,20))&" ")-1))/1000),"") -> 13.066667
A12: FALSE | B12: 05593023004S | C12: בוטן טבעי ג 16 | D12: 7.5 | G12: תכולה 200 | H12: 1 | I12: 1 | J12: 1 | K12: שונות | L12: 36 | M12: אגוזים טבעים ארוזים | N12: \N | O12: \N | P12: =IFERROR(D12/(VALUE(LEFT(TRIM(MID(G12,FIND("תכולה",G12)+6,20)),FIND(" ",TRIM(MID(G12,FIND("תכולה",G12)+6,20))&" ")-1))/1000),"") -> 37.5
B13: 07470154200S | D13: 15.5 | G13: תכולה 200 | H13: 1 | I13: 1 | J13: 1 | K13: שונות | L13: 36 | M13: אגוזים טבעים ארוזים | N13: \N | O13: \N | P13: =IFERROR(D13/(VALUE(LEFT(TRIM(MID(G13,FIND("תכולה",G13)+6,20)),FIND(" ",TRIM(MID(G13,FIND("תכולה",G13)+6,20))&" ")-1))/1000),"") -> 77.5
B14: 1000000581210S | D14: 18 | G14: תכולה 150 | H14: 1 | I14: 1 | J14: 1 | K14: שונות | L14: 36 | M14: אגוזים טבעים ארוזים | N14: \N | O14: \N | P14: =IFERROR(D14/(VALUE(LEFT(TRIM(MID(G14,FIND("תכולה",G14)+6,20)),FIND(" ",TRIM(MID(G14,FIND("תכולה",G14)+6,20))&" ")-1))/1000),"") -> 120
B15: 10000081122 M | D15: 15.5 | G15: תכולה 170 כשר לפסח לאוכלי קטניות תשפ"ו | H15: 1 | I15: 1 | J15: 1 | K15: שונות | L15: 36 | M15: אגוזים טבעים ארוזים | N15: \N | O15: \N | P15: =IFERROR(D15/(VALUE(LEFT(TRIM(MID(G15,FIND("תכולה",G15)+6,20)),FIND(" ",TRIM(MID(G15,FIND("תכולה",G15)+6,20))&" ")-1))/1000),"") -> 91.176471
B16: 10005840900L | C16: אגוזי מלך קלויים | D16: 0 | G16: תכולה 600 | H16: 1 | I16: 1 | J16: 1 | K16: שונות | L16: 36 | M16: אגוזים טבעים ארוזים | N16: \N | O16: \N | P16: =IFERROR(D16/(VALUE(LEFT(TRIM(MID(G16,FIND("תכולה",G16)+6,20)),FIND(" ",TRIM(MID(G16,FIND("תכולה",G16)+6,20))&" ")-1))/1000),"") -> 0
B17: 10005840900M | D17: 12 | G17: תכולה 300 | H17: 1 | I17: 1 | J17: 1 | K17: שונות | L17: 36 | M17: אגוזים טבעים ארוזים | N17: \N | O17: \N | P17: =IFERROR(D17/(VALUE(LEFT(TRIM(MID(G17,FIND("תכולה",G17)+6,20)),FIND(" ",TRIM(MID(G17,FIND("תכולה",G17)+6,20))&" ")-1))/1000),"") -> 40
B18: 10005840900S | D18: 8 | G18: תכולה 200 | H18: 1 | I18: 1 | J18: 1 | K18: שונות | L18: 36 | M18: אגוזים טבעים ארוזים | N18: \N | O18: \N | P18: =IFERROR(D18/(VALUE(LEFT(TRIM(MID(G18,FIND("תכולה",G18)+6,20)),FIND(" ",TRIM(MID(G18,FIND("תכולה",G18)+6,20))&" ")-1))/1000),"") -> 40
B19: 10018052024S | C19: זית סורי ירוק שבור | D19: 0 | G19: תכולה 140 | H19: 1 | I19: 1 | J19: 1 | K19: שונות | L19: 36 | M19: אגוזים טבעים ארוזים | N19: \N | O19: \N | P19: =IFERROR(D19/(VALUE(LEFT(TRIM(MID(G19,FIND("תכולה",G19)+6,20)),FIND(" ",TRIM(MID(G19,FIND("תכולה",G19)+6,20))&" ")-1))/1000),"") -> 0
A20: FALSE | B20: 10054191523M | C20: תערובת על האש במלחייה | D20: 16.5 | G20: תכולה 220 | H20: 1 | I20: 1 | J20: 1 | K20: שונות | L20: 36 | M20: אגוזים טבעים ארוזים | N20: \N | O20: \N | P20: =IFERROR(D20/(VALUE(LEFT(TRIM(MID(G20,FIND("תכולה",G20)+6,20)),FIND(" ",TRIM(MID(G20,FIND("תכולה",G20)+6,20))&" ")-1))/1000),"") -> 75
A21: FALSE | B21: 10100585506L | C21: מלפוף מתוקית את מור | D21: 54.2 | G21: תכולה 570 | H21: 1 | I21: 1 | J21: 1 | K21: שונות | L21: 36 | M21: אגוזים טבעים ארוזים | N21: \N | O21: \N | P21: =IFERROR(D21/(VALUE(LEFT(TRIM(MID(G21,FIND("תכולה",G21)+6,20)),FIND(" ",TRIM(MID(G21,FIND("תכולה",G21)+6,20))&" ")-1))/1000),"") -> 95.087719
A22: FALSE | B22: 10100585506M | C22: קוקוס מיובש טבעי ללא תוספת סוכר | D22: 39.2 | G22: תכולה 270 | H22: 1 | I22: 1 | J22: 1 | K22: שונות | L22: 36 | M22: אגוזים טבעים ארוזים | N22: \N | O22: \N | P22: =IFERROR(D22/(VALUE(LEFT(TRIM(MID(G22,FIND("תכולה",G22)+6,20)),FIND(" ",TRIM(MID(G22,FIND("תכולה",G22)+6,20))&" ")-1))/1000),"") -> 145.18519
B23: 10100585506S | C23: גרנולת אגוזים ופירות יבשים ללא תוספת וסכר | D23: 24.7 | G23: תכולה 170 | H23: 1 | I23: 1 | J23: 1 | K23: שונות | L23: 36 | M23: אגוזים טבעים ארוזים | N23: \N | O23: \N | P23: =IFERROR(D23/(VALUE(LEFT(TRIM(MID(G23,FIND("תכולה",G23)+6,20)),FIND(" ",TRIM(MID(G23,FIND("תכולה",G23)+6,20))&" ")-1))/1000),"") -> 145.29412
B24: 110000058238L | C24: תמר מלך בודדים | D24: 37.5 | G24: תכולה 570 | H24: 1 | I24: 1 | J24: 1 | K24: שונות | L24: 36 | M24: אגוזים טבעים ארוזים | N24: \N | O24: \N | P24: =IFERROR(D24/(VALUE(LEFT(TRIM(MID(G24,FIND("תכולה",G24)+6,20)),FIND(" ",TRIM(MID(G24,FIND("תכולה",G24)+6,20))&" ")-1))/1000),"") -> 65.789474
B25: 111150818002L | D25: 29 | G25: תכולה 520 | H25: 1 | I25: 1 | J25: 1 | K25: שונות | L25: 36 | M25: אגוזים טבעים ארוזים | N25: \N | O25: \N | P25: =IFERROR(D25/(VALUE(LEFT(TRIM(MID(G25,FIND("תכולה",G25)+6,20)),FIND(" ",TRIM(MID(G25,FIND("תכולה",G25)+6,20))&" ")-1))/1000),"") -> 55.769231
B26: 11115555180S | D26: 15.5 | G26: תכולה 180 | H26: 1 | I26: 1 | J26: 1 | K26: שונות | L26: 36 | M26: אגוזים טבעים ארוזים | N26: \N | O26: \N | P26: =IFERROR(D26/(VALUE(LEFT(TRIM(MID(G26,FIND("תכולה",G26)+6,20)),FIND(" ",TRIM(MID(G26,FIND("תכולה",G26)+6,20))&" ")-1))/1000),"") -> 86.111111
B27: 11118318590L | D27: 44.5 | G27: תכולה 600 | H27: 1 | I27: 1 | J27: 1 | K27: שונות | L27: 36 | M27: אגוזים טבעים ארוזים | N27: \N | O27: \N | P27: =IFERROR(D27/(VALUE(LEFT(TRIM(MID(G27,FIND("תכולה",G27)+6,20)),FIND(" ",TRIM(MID(G27,FIND("תכולה",G27)+6,20))&" ")-1))/1000),"") -> 74.166667
B28: 1185202400M | D28: 10.3 | G28: תכולה 200 | H28: 1 | I28: 1 | J28: 1 | K28: שונות | L28: 36 | M28: אגוזים טבעים ארוזים | N28: \N | O28: \N | P28: =IFERROR(D28/(VALUE(LEFT(TRIM(MID(G28,FIND("תכולה",G28)+6,20)),FIND(" ",TRIM(MID(G28,FIND("תכולה",G28)+6,20))&" ")-1))/1000),"") -> 51.5
B29: 13242000200S | C29: תפוז מיובש רצועות מסוכר | D29: 13.8 | G29: תכולה 200 | H29: 1 | I29: 1 | J29: 1 | K29: שונות | L29: 36 | M29: אגוזים טבעים ארוזים | N29: \N | O29: \N | P29: =IFERROR(D29/(VALUE(LEFT(TRIM(MID(G29,FIND("תכולה",G29)+6,20)),FIND(" ",TRIM(MID(G29,FIND("תכולה",G29)+6,20))&" ")-1))/1000),"") -> 69
B30: 13252627300M | C30: מייאסי שום | D30: 26.9 | G30: תכולה 300 | H30: 1 | I30: 1 | J30: 1 | K30: שונות | L30: 36 | M30: אגוזים טבעים ארוזים | N30: \N | O30: \N | P30: =IFERROR(D30/(VALUE(LEFT(TRIM(MID(G30,FIND("תכולה",G30)+6,20)),FIND(" ",TRIM(MID(G30,FIND("תכולה",G30)+6,20))&" ")-1))/1000),"") -> 89.666667
B31: 14000000323L | D31: 21 | G31: תכולה 350 כשר לפסח לאוכלי קטניות תשפ"ו | H31: 1 | I31: 0 | J31: 1 | K31: שונות | L31: 36 | M31: אגוזים טבעים ארוזים | N31: \N | O31: \N | P31: =IFERROR(D31/(VALUE(LEFT(TRIM(MID(G31,FIND("תכולה",G31)+6,20)),FIND(" ",TRIM(MID(G31,FIND("תכולה",G31)+6,20))&" ")-1))/1000),"") -> 60
B32: 140230430592M | C32: זעתר בלאדי במלחייה | D32: 11 | G32: תכולה 230 | H32: 1 | I32: 1 | J32: 1 | K32: שונות | L32: 36 | M32: אגוזים טבעים ארוזים | N32: \N | O32: \N | P32: =IFERROR(D32/(VALUE(LEFT(TRIM(MID(G32,FIND("תכולה",G32)+6,20)),FIND(" ",TRIM(MID(G32,FIND("תכולה",G32)+6,20))&" ")-1))/1000),"") -> 47.826087
A33: FALSE | B33: 14200300600S | C33: כוסברה טחונה במלחייה | D33: 5.5 | G33: תכולה 200 | H33: 1 | I33: 1 | J33: 1 | K33: שונות | L33: 36 | M33: אגוזים טבעים ארוזים | N33: \N | O33: \N | P33: =IFERROR(D33/(VALUE(LEFT(TRIM(MID(G33,FIND("תכולה",G33)+6,20)),FIND(" ",TRIM(MID(G33,FIND("תכולה",G33)+6,20))&" ")-1))/1000),"") -> 27.5
B34: 15018202430S | D34: 6 | G34: תכולה 150 | H34: 1 | I34: 1 | J34: 1 | K34: שונות | L34: 36 | M34: אגוזים טבעים ארוזים | N34: \N | O34: \N | P34: =IFERROR(D34/(VALUE(LEFT(TRIM(MID(G34,FIND("תכולה",G34)+6,20)),FIND(" ",TRIM(MID(G34,FIND("תכולה",G34)+6,20))&" ")-1))/1000),"") -> 40
B35: 158000000238M | C35: חגיגת הסלט | D35: 19.5 | G35: תכולה 280 | H35: 1 | I35: 1 | J35: 1 | K35: שונות | L35: 36 | M35: אגוזים טבעים ארוזים | N35: \N | O35: \N | P35: =IFERROR(D35/(VALUE(LEFT(TRIM(MID(G35,FIND("תכולה",G35)+6,20)),FIND(" ",TRIM(MID(G35,FIND("תכולה",G35)+6,20))&" ")-1))/1000),"") -> 69.642857
B36: 160052024S | C36: פפאיה רצועות | D36: 27.2 | G36: תכולה 160 | H36: 1 | I36: 1 | J36: 1 | K36: שונות | L36: 36 | M36: אגוזים טבעים ארוזים | N36: \N | O36: \N | P36: =IFERROR(D36/(VALUE(LEFT(TRIM(MID(G36,FIND("תכולה",G36)+6,20)),FIND(" ",TRIM(MID(G36,FIND("תכולה",G36)+6,20))&" ")-1))/1000),"") -> 170
B37: 18000001122M | D37: 22.6 | G37: תכולה 300 כשר לפסח לאוכלי קטניות תשפ"ו | H37: 1 | I37: 0 | J37: 1 | K37: שונות | L37: 36 | M37: אגוזים טבעים ארוזים | N37: \N | O37: \N | P37: =IFERROR(D37/(VALUE(LEFT(TRIM(MID(G37,FIND("תכולה",G37)+6,20)),FIND(" ",TRIM(MID(G37,FIND("תכולה",G37)+6,20))&" ")-1))/1000),"") -> 75.333333
B38: 18000001122S | D38: 16 | G38: תכולה 200 | H38: 1 | I38: 0 | J38: 1 | K38: שונות | L38: 36 | M38: אגוזים טבעים ארוזים | N38: \N | O38: \N | P38: =IFERROR(D38/(VALUE(LEFT(TRIM(MID(G38,FIND("תכולה",G38)+6,20)),FIND(" ",TRIM(MID(G38,FIND("תכולה",G38)+6,20))&" ")-1))/1000),"") -> 80
B39: 180300500080L | C39: אננס טבעי ללא תוספת סוכר | D39: 46.5 | G39: תכולה 580 | H39: 1 | I39: 1 | J39: 1 | K39: שונות | L39: 36 | M39: אגוזים טבעים ארוזים | N39: \N | O39: \N | P39: =IFERROR(D39/(VALUE(LEFT(TRIM(MID(G39,FIND("תכולה",G39)+6,20)),FIND(" ",TRIM(MID(G39,FIND("תכולה",G39)+6,20))&" ")-1))/1000),"") -> 80.172414
B40: 180522024841M | C40: אפונה ווסאבי | D40: 24 | G40: תכולה 270 | H40: 1 | I40: 1 | J40: 1 | K40: שונות | L40: 36 | M40: אגוזים טבעים ארוזים | N40: \N | O40: \N | P40: =IFERROR(D40/(VALUE(LEFT(TRIM(MID(G40,FIND("תכולה",G40)+6,20)),FIND(" ",TRIM(MID(G40,FIND("תכולה",G40)+6,20))&" ")-1))/1000),"") -> 88.888889
...

Sheet הצעת מחיר לסיטונאי
A2: =IFERROR(IF(products!A2=TRUE,products!A2,""),"") | B2: =IFERROR(IF(products!A2=TRUE,products!B2,""),"") | C2: =IFERROR(IF(products!A2=TRUE,products!C2,""),"") | D2: =IFERROR(IF(products!A2=TRUE,products!D2,""),"") | E2: =IFERROR(IF(products!A2=TRUE,products!E2,""),"") | F2: =IFERROR(IF(products!A2=TRUE,products!F2,""),"") | G2: =IFERROR(IF(products!A2=TRUE,products!G2,""),"")
A3: =IFERROR(IF(products!A3=TRUE,products!A3,""),"") | B3: =IFERROR(IF(products!A3=TRUE,products!B3,""),"") | C3: =IFERROR(IF(products!A3=TRUE,products!C3,""),"") | D3: =IFERROR(IF(products!A3=TRUE,products!D3,""),"") | E3: =IFERROR(IF(products!A3=TRUE,products!E3,""),"") | F3: =IFERROR(IF(products!A3=TRUE,products!F3,""),"") | G3: =IFERROR(IF(products!A3=TRUE,products!G3,""),"")
A4: =IFERROR(IF(products!A4=TRUE,products!A4,""),"") | B4: =IFERROR(IF(products!A4=TRUE,products!B4,""),"") | C4: =IFERROR(IF(products!A4=TRUE,products!C4,""),"") | D4: =IFERROR(IF(products!A4=TRUE,products!D4,""),"") | E4: =IFERROR(IF(products!A4=TRUE,products!E4,""),"") | F4: =IFERROR(IF(products!A4=TRUE,products!F4,""),"") | G4: =IFERROR(IF(products!A4=TRUE,products!G4,""),"")
B5: ברקוד | C5: תיאור פריט | D5: סהכ משקל | E5: מחיר לק"ג | F5: כמות מוזמנת | G5: סה"כ מחיר להזמנה
A6: =IFERROR(IF(products!A5=TRUE,products!A5,""),"") | B6: =IFERROR(IF(products!A5=TRUE,products!B5,""),"") | C6: =IFERROR(IF(products!A5=TRUE,products!C5,""),"") | D6: =IFERROR(IF(products!A5=TRUE,products!D5,""),"") | E6: =IFERROR(IF(products!A5=TRUE,products!E5,""),"") | F6: =IFERROR(IF(products!A5=TRUE,products!F5,""),"") | G6: =IFERROR(IF(products!A5=TRUE,products!G5,""),"")
A7: =IFERROR(IF(products!A6=TRUE,products!A6,""),"") | B7: =IFERROR(IF(products!A6=TRUE,products!B6,""),"") | C7: =IFERROR(IF(products!A6=TRUE,products!C6,""),"") | D7: =IFERROR(IF(products!A6=TRUE,products!D6,""),"") | E7: =IFERROR(IF(products!A6=TRUE,products!E6,""),"") | F7: =IFERROR(IF(products!A6=TRUE,products!F6,""),"") | G7: =IFERROR(IF(products!A6=TRUE,products!G6,""),"")
A8: =IFERROR(IF(products!A7=TRUE,products!A7,""),"") | B8: =IFERROR(IF(products!A7=TRUE,products!B7,""),"") | C8: =IFERROR(IF(products!A7=TRUE,products!C7,""),"") | D8: =IFERROR(IF(products!A7=TRUE,products!D7,""),"") | E8: =IFERROR(IF(products!A7=TRUE,products!E7,""),"") | F8: =IFERROR(IF(products!A7=TRUE,products!F7,""),"") | G8: =IFERROR(IF(products!A7=TRUE,products!G7,""),"")
A9: =IFERROR(IF(products!A8=TRUE,products!A8,""),"") | B9: =IFERROR(IF(products!A8=TRUE,products!B8,""),"") | C9: =IFERROR(IF(products!A8=TRUE,products!C8,""),"") | D9: =IFERROR(IF(products!A8=TRUE,products!D8,""),"") | E9: =IFERROR(IF(products!A8=TRUE,products!E8,""),"") | F9: =IFERROR(IF(products!A8=TRUE,products!F8,""),"") | G9: =IFERROR(IF(products!A8=TRUE,products!G8,""),"")
A10: =IFERROR(IF(products!A9=TRUE,products!A9,""),"") | B10: =IFERROR(IF(products!A9=TRUE,products!B9,""),"") | C10: =IFERROR(IF(products!A9=TRUE,products!C9,""),"") | D10: =IFERROR(IF(products!A9=TRUE,products!D9,""),"") | E10: =IFERROR(IF(products!A9=TRUE,products!E9,""),"") | F10: =IFERROR(IF(products!A9=TRUE,products!F9,""),"") | G10: =IFERROR(IF(products!A9=TRUE,products!G9,""),"")
A11: =IFERROR(IF(products!A10=TRUE,products!A10,""),"") | B11: =IFERROR(IF(products!A10=TRUE,products!B10,""),"") | C11: =IFERROR(IF(products!A10=TRUE,products!C10,""),"") | D11: =IFERROR(IF(products!A10=TRUE,products!D10,""),"") | E11: =IFERROR(IF(products!A10=TRUE,products!E10,""),"") | F11: =IFERROR(IF(products!A10=TRUE,products!F10,""),"") | G11: =IFERROR(IF(products!A10=TRUE,products!G10,""),"")
A12: =IFERROR(IF(products!A11=TRUE,products!A11,""),"") | B12: =IFERROR(IF(products!A11=TRUE,products!B11,""),"") | C12: =IFERROR(IF(products!A11=TRUE,products!C11,""),"") | D12: =IFERROR(IF(products!A11=TRUE,products!D11,""),"") | E12: =IFERROR(IF(products!A11=TRUE,products!E11,""),"") | F12: =IFERROR(IF(products!A11=TRUE,products!F11,""),"") | G12: =IFERROR(IF(products!A11=TRUE,products!G11,""),"")
A13: =IFERROR(IF(products!A12=TRUE,products!A12,""),"") | B13: =IFERROR(IF(products!A12=TRUE,products!B12,""),"") | C13: =IFERROR(IF(products!A12=TRUE,products!C12,""),"") | D13: =IFERROR(IF(products!A12=TRUE,products!D12,""),"") | E13: =IFERROR(IF(products!A12=TRUE,products!E12,""),"") | F13: =IFERROR(IF(products!A12=TRUE,products!F12,""),"") | G13: =IFERROR(IF(products!A12=TRUE,products!G12,""),"")
A14: =IFERROR(IF(products!A13=TRUE,products!A13,""),"") | B14: =IFERROR(IF(products!A13=TRUE,products!B13,""),"") | C14: =IFERROR(IF(products!A13=TRUE,products!C13,""),"") | D14: =IFERROR(IF(products!A13=TRUE,products!D13,""),"") | E14: =IFERROR(IF(products!A13=TRUE,products!E13,""),"") | F14: =IFERROR(IF(products!A13=TRUE,products!F13,""),"") | G14: =IFERROR(IF(products!A13=TRUE,products!G13,""),"")
A15: =IFERROR(IF(products!A14=TRUE,products!A14,""),"") | B15: =IFERROR(IF(products!A14=TRUE,products!B14,""),"") | C15: =IFERROR(IF(products!A14=TRUE,products!C14,""),"") | D15: =IFERROR(IF(products!A14=TRUE,products!D14,""),"") | E15: =IFERROR(IF(products!A14=TRUE,products!E14,""),"") | F15: =IFERROR(IF(products!A14=TRUE,products!F14,""),"") | G15: =IFERROR(IF(products!A14=TRUE,products!G14,""),"")
A16: =IFERROR(IF(products!A15=TRUE,products!A15,""),"") | B16: =IFERROR(IF(products!A15=TRUE,products!B15,""),"") | C16: =IFERROR(IF(products!A15=TRUE,products!C15,""),"") | D16: =IFERROR(IF(products!A15=TRUE,products!D15,""),"") | E16: =IFERROR(IF(products!A15=TRUE,products!E15,""),"") | F16: =IFERROR(IF(products!A15=TRUE,products!F15,""),"") | G16: =IFERROR(IF(products!A15=TRUE,products!G15,""),"")
A17: =IFERROR(IF(products!A16=TRUE,products!A16,""),"") | B17: =IFERROR(IF(products!A16=TRUE,products!B16,""),"") | C17: =IFERROR(IF(products!A16=TRUE,products!C16,""),"") | D17: =IFERROR(IF(products!A16=TRUE,products!D16,""),"") | E17: =IFERROR(IF(products!A16=TRUE,products!E16,""),"") | F17: =IFERROR(IF(products!A16=TRUE,products!F16,""),"") | G17: =IFERROR(IF(products!A16=TRUE,products!G16,""),"")
... A2534: =IFERROR(IF(products!A2533=TRUE,products!A2533,""),"") | B2534: =IFERROR(IF(products!A2533=TRUE,products!B2533,""),"") | C2534: =IFERROR(IF(products!A2533=TRUE,products!C2533,""),"") | D2534: =IFERROR(IF(products!A2533=TRUE,products!D2533,""),"") | E2534: =IFERROR(IF(products!A2533=TRUE,products!E2533,""),"") | F2534: =IFERROR(IF(products!A2533=TRUE,products!F2533,""),"") | G2534: =IFERROR(IF(products!A2533=TRUE,products!G2533,""),"")
C2536: סה"כ: | D2536: =SUM(D2:D2534) -> 0

Sheet  ידני-הצעת מחיר סיטונאי
A7: הצעת מחיר נכון לתאריך:
A8: **הצעת המחיר תקפה ל- 14 יום בלבד
A10: לכבוד:
A11: כתובת מייל:
A12: טלפון:
A16: תיאור פריט | B16: ברקוד | C16: סהכ משקל | D16: מחיר לק"ג | E16: כמות מוזמנת | F16: סה"כ מחיר להזמנה
